<ns0:test-suite xmlns:ns0="urn:model.allure.qatools.yandex.ru" start="1559550801138" stop="1559550801138">
  <description>This is the tests collection phase. Failures are modules that failed to collect.</description>
  <name>test_collection_phase</name>
  <title>Collection phase</title>
  <labels/>
  <test-cases>
    <test-case start="1559550801138" status="broken" stop="1559550801138">
      <name>test_collections</name>
      <failure>
        <message>failed</message>
        <stack-trace>ImportError while importing test module '/Users/wangjuan/workpace/API_Automation/TestCase/test_collections.py'.
Hint: make sure your test modules/packages have valid Python names.
Traceback:
TestCase/test_collections.py:9: in &lt;module&gt;
    from Params.params import Collections
E   ImportError: cannot import name 'Collections'</stack-trace>
      </failure>
      <attachments/>
      <labels/>
      <steps/>
    </test-case>
    <test-case start="1559550801138" status="broken" stop="1559550801138">
      <name>test_personal</name>
      <failure>
        <message>failed</message>
        <stack-trace>ImportError while importing test module '/Users/wangjuan/workpace/API_Automation/TestCase/test_personal.py'.
Hint: make sure your test modules/packages have valid Python names.
Traceback:
TestCase/test_personal.py:10: in &lt;module&gt;
    from Params.params import Personal
E   ImportError: cannot import name 'Personal'</stack-trace>
      </failure>
      <attachments/>
      <labels/>
      <steps/>
    </test-case>
  </test-cases>
</ns0:test-suite>
